Workbook
Name NoPrefixVar: #REF!

Sheet TOC
A1: Version | B1: Observation Class | C1: Domain Name | D1: Domain Label | E1: Domain Structure | F1: Keys
A2: SDTMIG v3.4 | B2: Special Purpose | C2: CO | D2: Comments | E2: One record per comment per subject | F2: =VLOOKUP(C2,[1]Table1!$A$7:$F$69,6,0) -> STUDYID, USUBJID, IDVAR, COREF, CODTC
A3: SDTMIG v3.4 | B3: Special Purpose | C3: DM | D3: Demographics | E3: One record per subject | F3: =VLOOKUP(C3,[1]Table1!$A$7:$F$69,6,0) -> STUDYID, USUBJID
A4: SDTMIG v3.4 | B4: Special Purpose | C4: SE | D4: Subject Elements | E4: One record per actual Element per subject | F4: =VLOOKUP(C4,[1]Table1!$A$7:$F$69,6,0) -> STUDYID, USUBJID, ETCD, SESTDTC
A5: SDTMIG v3.4 | B5: Special Purpose | C5: SM | D5: Subject Disease Milestones | E5: One record per Disease Milestone per subject | F5: =VLOOKUP(C5,[1]Table1!$A$7:$F$69,6,0) -> STUDYID, USUBJID, MIDS
A6: SDTMIG v3.4 | B6: Special Purpose | C6: SV | D6: Subject Visits | E6: One record per subject per actual visit | F6: =VLOOKUP(C6,[1]Table1!$A$7:$F$69,6,0) -> STUDYID, USUBJID, SVTERM
A7: SDTMIG v3.4 | B7: Interventions | C7: AG | D7: Procedure Agents | E7: One record per recorded intervention occurrence per subject | F7: =VLOOKUP(C7,[1]Table1!$A$7:$F$69,6,0) -> STUDYID, USUBJID, AGTRT, AGSTDTC
A8: SDTMIG v3.4 | B8: Interventions | C8: CM | D8: Concomitant/Prior Medications | E8: One record per recorded intervention occurrence or constant-dosing interval per subject | F8: =VLOOKUP(C8,[1]Table1!$A$7:$F$69,6,0) -> STUDYID, USUBJID, CMTRT, CMSTDTC
A9: SDTMIG v3.4 | B9: Interventions | C9: EC | D9: Exposure as Collected | E9: One record per protocol-specified study treatment, collected-dosing interval, per subject, per mood | F9: =VLOOKUP(C9,[1]Table1!$A$7:$F$69,6,0) -> STUDYID, USUBJID, ECTRT, ECSTDTC, ECMOOD
A10: SDTMIG v3.4 | B10: Interventions | C10: EX | D10: Exposure | E10: One record per protocol-specified study treatment, constant-dosing interval, per subject | F10: =VLOOKUP(C10,[1]Table1!$A$7:$F$69,6,0) -> STUDYID, USUBJID, EXTRT, EXSTDTC
A11: SDTMIG v3.4 | B11: Interventions | C11: ML | D11: Meal Data | E11: One record per food product occurrence or constant intake interval per subject | F11: =VLOOKUP(C11,[1]Table1!$A$7:$F$69,6,0) -> STUDYID, USUBJID, MLTRT, MLSTDTC
A12: SDTMIG v3.4 | B12: Interventions | C12: PR | D12: Procedures | E12: One record per recorded procedure per occurrence per subject | F12: =VLOOKUP(C12,[1]Table1!$A$7:$F$69,6,0) -> STUDYID, USUBJID, PRTRT, PRSTDTC
A13: SDTMIG v3.4 | B13: Interventions | C13: SU | D13: Substance Use | E13: One record per substance type per reported occurrence per subject | F13: =VLOOKUP(C13,[1]Table1!$A$7:$F$69,6,0) -> STUDYID, USUBJID, SUTRT, SUSTDTC
... A63: SDTMIG v3.4 | B63: Study Reference | C63: OI | D63: Non-host Organism Identifiers | E63: One record per taxon per non-host organism | F63: =VLOOKUP(C63,[1]Table1!$A$7:$F$69,6,0) -> NHOID, OISEQ

Sheet CO
A1: Variable Name | B1: Variable Label | C1: Type | D1: Controlled Terms, Codelist or Format | E1: Role | F1: CDISC Notes | G1: Core
A2: STUDYID | B2: Study Identifier | C2: Char | E2: Identifier | F2: Unique identifier for a study. | G2: Req
A3: DOMAIN | B3: Domain Abbreviation | C3: Char | D3: CO | E3: Identifier | F3: Two-character abbreviation for the domain. | G3: Req
A4: RDOMAIN | B4: Related Domain Abbreviation | C4: Char | E4: Record Qualifier | F4: Two-character abbreviation for the domain of the parent record(s). Null for comments collected on a general comments or additional information CRF page. | G4: Perm
A5: USUBJID | B5: Unique Subject Identifier | C5: Char | E5: Identifier | F5: Identifier used to uniquely identify a subject across all studies for all applications or submissions involving the product. | G5: Req
A6: COSEQ | B6: Sequence Number | C6: Num | E6: Identifier | F6: Sequence Number given to ensure uniqueness of subject records within a domain. May be any valid number. | G6: Req
A7: IDVAR | B7: Identifying Variable | C7: Char | E7: Record Qualifier | F7: Identifying variable in the parent dataset that identifies the record(s) to which the comment applies. Examples AESEQ or CMGRPID. Used only when individual comments are related to domain records. Null for comments collected on separate CRFs. | G7: Perm
A8: IDVARVAL | B8: Identifying Variable Value | C8: Char | E8: Record Qualifier | F8: Value of identifying variable of the parent record(s). Used only when individual comments are related to domain records. Null for comments collected on separate CRFs. | G8: Perm
A9: COREF | B9: Comment Reference | C9: Char | E9: Record Qualifier | F9: Sponsor-defined reference associated with the comment. May be the CRF page number (e.g., 650), or a module name (e.g., DEMOG), or a combination of information that identifies the reference (e.g. 650-VITALS-VISIT 2). | G9: Perm
A10: COVAL | B10: Comment | C10: Char | E10: Topic | F10: The text of the comment. Text over 200 characters can be added to additional columns COVAL1-COVALn. See Assumption 3. | G10: Req
A11: COEVAL | B11: Evaluator | C11: Char | E11: Record Qualifier | F11: Used to describe the originator of the comment. Examples: CENTRAL, REVIEWER, ADJUDICATION COMMITTEE, PRINCIPAL INVESTIGATOR. | G11: Perm
A12: COEVALID | B12: Evaluator Identifier | C12: Char | D12: (MEDEVAL) | E12: Record Qualifier | F12: Used to distinguish multiple evaluators with the same role recorded in --EVAL. Examples: RADIOLOGIST, RADIOLOGIST1, RADIOLOGIST2. | G12: Perm
A13: CODTC | B13: Date/Time of Comment | C13: Char | D13: ISO 8601 | E13: Timing | F13: Date/time of comment on dedicated comment form. Should be null if this is a child record of another domain or if comment date was not collected. | G13: Perm
A14: CODY | B14: Study Day of Comment | C14: Num | E14: Timing | F14: Study day of the comment, in integer days. The algorithm for calculations must be relative to the sponsor-defined RFSTDTC variable in the Demographics (DM) domain. | G14: Perm

Sheet DM
A1: Variable Name | B1: Variable Label | C1: Type | D1: Controlled Terms, Codelist or Format | E1: Role | F1: CDISC Notes | G1: Core
A2: STUDYID | B2: Study Identifier | C2: Char | E2: Identifier | F2: Unique identifier for a study. | G2: Req
A3: DOMAIN | B3: Domain Abbreviation | C3: Char | D3: DM | E3: Identifier | F3: Two-character abbreviation for the domain. | G3: Req
A4: USUBJID | B4: Unique Subject Identifier | C4: Char | E4: Identifier | F4: Identifier used to uniquely identify a subject across all studies for all applications or submissions involving the product. This must be a unique number, and could be a compound identifier formed by concatenating STUDYID-SITEID-SUBJID. | G4: Req
A5: SUBJID | B5: Subject Identifier for the Study | C5: Char | E5: Topic | F5: Subject identifier, which must be unique within the study. Often the ID of the subject as recorded on a CRF. | G5: Req
A6: RFSTDTC | B6: Subject Reference Start Date/Time | C6: Char | D6: ISO 8601 | E6: Record Qualifier | F6: Reference Start Date/time for the subject in ISO 8601 character format. Usually equivalent to date/time when subject was first exposed to study treatment. See Assumption 9 for additional detail on when RFSTDTC may be null. | G6: Exp
A7: RFENDTC | B7: Subject Reference End Date/Time | C7: Char | D7: ISO 8601 | E7: Record Qualifier | F7: Reference End Date/time for the subject in ISO 8601 character format. Usually equivalent to the date/time when subject was determined to have ended the trial, and often equivalent to date/time of last exposure to study treatment. Required for all randomized subjects; null for screen failures or unassigned subjects. | G7: Exp
A8: RFXSTDTC | B8: Date/Time of First Study Treatment | C8: Char | D8: ISO 8601 | E8: Record Qualifier | F8: First date/time of exposure to any protocol-specified treatment or therapy, equal to the earliest value of EXSTDTC. | G8: Exp
A9: RFXENDTC | B9: Date/Time of Last Study Treatment | C9: Char | D9: ISO 8601 | E9: Record Qualifier | F9: Last date/time of exposure to any protocol-specified treatment or therapy, equal to the latest value of EXENDTC (or the latest value of EXSTDTC if EXENDTC was not collected or is missing). | G9: Exp
A10: RFCSTDTC | B10: Date/Time of First Challenge Agent Admin | C10: Char | D10: ISO 8601 | E10: Record Qualifier | F10: Used only when protocol specifies a challenge agent to induce a condition that the investigational treatment is intended to cure, mitigate, treat, or prevent. Equal to the earliest value of AGSTDTC for the challenge agent. | G10: Perm
A11: RFCENDTC | B11: Date/Time of Last Challenge Agent Admin | C11: Char | D11: ISO 8601 | E11: Record Qualifier | F11: Used only when protocol specifies a challenge agent to induce a condition that the investigational treatment is intended to cure, mitigate, treat, or prevent. Equal to the latest value of AGENDTC for the challenge agent (or the latest value of AGSTDTC if AGENDTC was not collected or is missing). | G11: Perm
A12: RFICDTC | B12: Date/Time of Informed Consent | C12: Char | D12: ISO 8601 | E12: Record Qualifier | F12: Date/time of informed consent in ISO 8601 character format. This will be the same as the date of informed consent in the Disposition domain, if that protocol milestone is documented. Would be null only in studies not collecting the date of informed consent. | G12: Exp
A13: RFPENDTC | B13: Date/Time of End of Participation | C13: Char | D13: ISO 8601 | E13: Record Qualifier | F13: Date/time when subject ended participation or follow-up in a trial, as defined in the protocol, in ISO 8601 character format. Should correspond to the last known date of contact. Examples include completion date, withdrawal date, last follow-up, date recorded for lost to follow up, or death date. | G13: Exp
A14: DTHDTC | B14: Date/Time of Death | C14: Char | D14: ISO 8601 | E14: Record Qualifier | F14: Date/time of death for any subject who died, in ISO 8601 format. Should represent the date/time that is captured in the clinical-trial database. | G14: Exp
A15: DTHFL | B15: Subject Death Flag | C15: Char | D15: (NY) | E15: Record Qualifier | F15: Indicates the subject died. Should be "Y" or null. Should be populated even when the death date is unknown. | G15: Exp
A16: SITEID | B16: Study Site Identifier | C16: Char | E16: Record Qualifier | F16: Unique identifier for a site within a study. | G16: Req
A17: INVID | B17: Investigator Identifier | C17: Char | E17: Record Qualifier | F17: An identifier to describe the Investigator for the study. May be used in addition to SITEID. Not needed if SITEID is equivalent to INVID. | G17: Perm
A18: INVNAM | B18: Investigator Name | C18: Char | E18: Synonym Qualifier | F18: Name of the investigator for a site. | G18: Perm
A19: BRTHDTC | B19: Date/Time of Birth | C19: Char | D19: ISO 8601 | E19: Record Qualifier | F19: Date/time of birth of the subject. | G19: Perm
A20: AGE | B20: Age | C20: Num | E20: Record Qualifier | F20: Age expressed in AGEU. May be derived from RFSTDTC and BRTHDTC, but BRTHDTC may not be available in all cases (due to subject privacy concerns). | G20: Exp
A21: AGEU | B21: Age Units | C21: Char | D21: (AGEU) | E21: Variable Qualifier | F21: Units associated with AGE. | G21: Exp
A22: SEX | B22: Sex | C22: Char | D22: (SEX) | E22: Record Qualifier | F22: Sex of the subject. | G22: Req
A23: RACE | B23: Race | C23: Char | D23: (RACE) | E23: Record Qualifier | F23: Race of the subject. Sponsors should refer to "Collection of Race and Ethnicity Data in Clinical Trials" (FDA, October, 2016) for guidance regarding the collection of race (https://www.fda.gov/downloads/regulatoryinformation/guidances/ucm126396.pdf) See Assumption below regarding RACE. | G23: Exp
A24: ETHNIC | B24: Ethnicity | C24: Char | D24: (ETHNIC) | E24: Record Qualifier | F24: The ethnicity of the subject. Sponsors should refer to "Collection of Race and Ethnicity Data in Clinical Trials" (FDA, October, 2016) for guidance regarding the collection of ethnicity (https://www.fda.gov/downloads/regulatoryinformation/guidances/ucm126396.pdf). | G24: Perm
A25: ARMCD | B25: Planned Arm Code | C25: Char | E25: Record Qualifier | F25: ARMCD is limited to 20 characters. It is not subject to the character restrictions that apply to TESTCD.The maximum length of ARMCD is longer than for other "short" variables to accommodate the kind of values that are likely to be needed for crossover trials. For example, if ARMCD values for a seven-period crossover were constructed using two-character abbreviations for each treatment and separating hyphens, the length of ARMCD values would be 20. If the subject was not assigned to an Arm, ARMCD is null and ARMNRS is populated. With the exception of studies which use multi-stage Arm assignments, must be a value of ARMCD in the Trial Arms Dataset. | G25: Exp
A26: ARM | B26: Description of Planned Arm | C26: Char | E26: Synonym Qualifier | F26: Name of the Arm to which the subject was assigned. If the subject was not assigned to an Arm, ARM is null and ARMNRS is populated. With the exception of studies which use multi-stage Arm assignments, must be a value of ARM in the Trial Arms Dataset. | G26: Exp
A27: ACTARMCD | B27: Actual Arm Code | C27: Char | E27: Record Qualifier | F27: Code of actual Arm. ACTARMCD is limited to 20 characters. It is not subject to the character restrictions that apply to TESTCD. The maximum length of ACTARMCD is longer than for other short variables to accommodate the kind of values that are likely to be needed for crossover trials. With the exception of studies which use multi-stage Arm assignments, must be a value of ARMCD in the Trial Arms Dataset. If the subject was not assigned to an Arm or followed a course not described by any planned Arm, ACTARMCD is null and ARMNRS is populated. | G27: Exp
A28: ACTARM | B28: Description of Actual Arm | C28: Char | E28: Synonym Qualifier | F28: Description of actual Arm. With the exception of studies which use multi-stage Arm assignments, must be a value of ARM in the Trial Arms Dataset. If the subject was not assigned to an Arm or followed a course not described by any planned Arm, ACTARM is null and ARMNRS is populated. | G28: Exp
A29: ARMNRS | B29: Reason Arm and/or Actual Arm is Null | C29: Char | E29: Record Qualifier | F29: A coded reason that Arm variables (ARM and ARMCD) and/or actual Arm variables (ACTARM and ACTARMCD) are null. Examples: "SCREEN FAILURE", "NOT ASSIGNED", "ASSIGNED, NOT TREATED", "UNPLANNED TREATMENT". It is assumed that if the Arm and actual Arm variables are null, the same reason applies to both Arm and actual Arm. | G29: Exp
A30: ACTARMUD | B30: Description of Unplanned Actual Arm | C30: Char | E30: Record Qualifier | F30: A description of actual treatment for a subject who did not receive treatment described in one of the planned trial Arms. | G30: Exp
A31: COUNTRY | B31: Country | C31: Char | D31: ISO 3166-1 Alpha-3 | E31: Record Qualifier | F31: Country of the investigational site in which the subject participated in the trial. | G31: Req
A32: DMDTC | B32: Date/Time of Collection | C32: Char | D32: ISO 8601 | E32: Timing | F32: Date/time of demographic data collection. | G32: Perm
A33: DMDY | B33: Study Day of Collection | C33: Num | E33: Timing | F33: Study day of collection measured as integer days. | G33: Perm

Sheet SE
A1: Variable Name | B1: Variable Label | C1: Type | D1: Controlled Terms, Codelist or Format | E1: Role | F1: CDISC Notes | G1: Core
A2: STUDYID | B2: Study Identifier | C2: Char | E2: Identifier | F2: Unique identifier for a study. | G2: Req
A3: DOMAIN | B3: Domain Abbreviation | C3: Char | D3: SE | E3: Identifier | F3: Two-character abbreviation for the domain. | G3: Req
A4: USUBJID | B4: Unique Subject Identifier | C4: Char | E4: Identifier | F4: Identifier used to uniquely identify a subject across all studies for all applications or submissions involving the product. | G4: Req
A5: SESEQ | B5: Sequence Number | C5: Num | E5: Identifier | F5: Sequence number given to ensure uniqueness of subject records within a domain. Should be assigned to be consistent chronological order. | G5: Req
A6: ETCD | B6: Element Code | C6: Char | E6: Topic | F6: 1. ETCD (the companion to ELEMENT) is limited to 8 characters and does not have special character restrictions. These values should be short for ease of use in programming, but it is not expected that ETCD will need to serve as a variable name. 2. If an encountered Element differs from the planned Element to the point that it is considered a new Element, then use "UNPLAN" as the value for ETCD to represent this Element. | G6: Req
A7: ELEMENT | B7: Description of Element | C7: Char | E7: Synonym Qualifier | F7: The name of the Element. If ETCD has a value of "UNPLAN" then ELEMENT should be null. | G7: Perm
A8: TAETORD | B8: Planned Order of Element within Arm | C8: Num | E8: Timing | F8: Number that gives the planned order of the Element within the subject's assigned Arm. | G8: Perm
A9: EPOCH | B9: Epoch | C9: Char | D9: (EPOCH) | E9: Timing | F9: Epoch associated with the Element in the planned sequence of Elements for the Arm to which the subject was assigned. | G9: Perm
A10: SESTDTC | B10: Start Date/Time of Element | C10: Char | D10: ISO 8601 | E10: Timing | F10: Start date/time for an Element for each subject. | G10: Req
A11: SEENDTC | B11: End Date/Time of Element | C11: Char | D11: ISO 8601 | E11: Timing | F11: End date/time for an Element for each subject. | G11: Exp
A12: SESTDY | B12: Study Day of Start of Element | C12: Num | E12: Timing | F12: Study day of start of element relative to the sponsor-defined RFSTDTC. | G12: Perm
A13: SEENDY | B13: Study Day of End of Element | C13: Num | E13: Timing | F13: Study day of end of element relative to the sponsor-defined RFSTDTC. | G13: Perm
A14: SEUPDES | B14: Description of Unplanned Element | C14: Char | E14: Synonym Qualifier | F14: Description of what happened to the subject during an unplanned Element. Used only if ETCD has the value of "UNPLAN". | G14: Perm

Sheet SV
A1: Variable Name | B1: Variable Label | C1: Type | D1: Controlled Terms, Codelist or Format | E1: Role | F1: CDISC Notes | G1: Core
A2: STUDYID | B2: Study Identifier | C2: Char | E2: Identifier | F2: Unique identifier for a study. | G2: Req
A3: DOMAIN | B3: Domain Abbreviation | C3: Char | D3: SV | E3: Identifier | F3: Two-character abbreviation for the domain most relevant to the observation. The domain abbreviation is also used as a prefix for variables to ensure uniqueness when datasets are merged. | G3: Req
A4: USUBJID | B4: Unique Subject Identifier | C4: Char | E4: Identifier | F4: Identifier used to uniquely identify a subject across all studies for all applications or submissions involving the product. | G4: Req
A5: VISITNUM | B5: Visit Number | C5: Num | E5: Topic | F5: Clinical encounter number. Numeric version of VISIT, used for sorting. | G5: Req
A6: VISIT | B6: Visit Name | C6: Char | E6: Synonym Qualifier | F6: Protocol-defined description of a clinical encounter. | G6: Perm
A7: SVPRESP | B7: Pre-specified | C7: Char | D7: (NY) | E7: Variable Qualifier | F7: Used to indicate whether the visit was planned (i.e., visits specified in the TV domain). Value is "Y" for planned visits, null for unplanned visits. | G7: Exp
A8: SVOCCUR | B8: Occurrence | C8: Char | D8: (NY) | E8: Record Qualifier | F8: Used to record whether a planned visit occurred. The value is null for unplanned visits. | G8: Exp
A9: SVREASOC | B9: Reason for Occur Value | C9: Char | E9: Record Qualifier | F9: The reason for the value in SVOCCUR. If SVOCCUR="N", SVREASOC is the reason the visit did not occur. | G9: Perm
A10: SVCNTMOD | B10: Contact Mode | C10: Char | D10: (CNTMODE) | E10: Record Qualifier | F10: The way in which the visit was conducted. Examples: "IN PERSON", "TELEPHONE CALL", "IVRS". | G10: Perm
A11: SVEPCHGI | B11: Epi/Pandemic Related Change Indicator | C11: Char | D11: (NY) | E11: Record Qualifier | F11: Indicates whether the visit was changed due to an epidemic or pandemic. | G11: Perm
A12: VISITDY | B12: Planned Study Day of Visit | C12: Num | E12: Timing | F12: Planned study day of VISIT. Should be an integer. | G12: Perm
A13: SVSTDTC | B13: Start Date/Time of Observation | C13: Char | D13: ISO8601 datetime or interval | E13: Timing | F13: Start date/time of an observation represented in IS0 8601 character format. | G13: Exp
A14: SVENDTC | B14: End Date/Time of Observation | C14: Char | D14: ISO8601 datetime or interval | E14: Timing | F14: End date/time of the observation represented in IS0 8601 character format. | G14: Exp
A15: SVSTDY | B15: Study Day of Start of Observation | C15: Num | E15: Timing | F15: Actual study day of start of observation expressed in integer days relative to the sponsor- defined RFSTDTC in Demographics. | G15: Perm
A16: SVENDY | B16: Study Day of End of Observation | C16: Num | E16: Timing | F16: Actual study day of end of observation expressed in integer days relative to the sponsor- defined RFSTDTC in Demographics. | G16: Perm
A17: SVUPDES | B17: Description of Unplanned Visit | C17: Char | E17: Record Qualifier | F17: Description of what happened to the subject during an unplanned visit. Only populated for unplanned visits. | G17: Perm

Sheet EC
A1: Variable Name | B1: Variable Label | C1: Type | D1: Controlled Terms, Codelist or Format | E1: Role | F1: CDISC Notes | G1: Core
A2: STUDYID | B2: Study Identifier | C2: Char | E2: Identifier | F2: Unique identifier for a study. | G2: Req
A3: DOMAIN | B3: Domain Abbreviation | C3: Char | D3: EC | E3: Identifier | F3: Two-character abbreviation for the domain. | G3: Req
A4: USUBJID | B4: Unique Subject Identifier | C4: Char | E4: Identifier | F4: Identifier used to uniquely identify a subject across all studies for all applications or submissions involving the product. | G4: Req
A5: ECSEQ | B5: Sequence Number | C5: Num | E5: Identifier | F5: Sequence Number given to ensure uniqueness of subject records within a domain. May be any valid number. | G5: Req
A6: ECGRPID | B6: Group ID | C6: Char | E6: Identifier | F6: Used to tie together a block of related records in a single domain for a subject. | G6: Perm
A7: ECREFID | B7: Reference ID | C7: Char | E7: Identifier | F7: Internal or external identifier (e.g., kit number, bottle label, vial identifier). | G7: Perm
A8: ECSPID | B8: Sponsor-Defined Identifier | C8: Char | E8: Identifier | F8: Sponsor-defined reference number. Perhaps pre-printed on the CRF as an explicit line identifier or defined in the sponsor's operational database. Example: Line number on a CRF Page. | G8: Perm
A9: ECLNKID | B9: Link ID | C9: Char | E9: Identifier | F9: Identifier used to link related records across domains. | G9: Perm
A10: ECLNKGRP | B10: Link Group ID | C10: Char | E10: Identifier | F10: Identifier used to link related, grouped records across domains. | G10: Perm
A11: ECTRT | B11: Name of Treatment | C11: Char | E11: Topic | F11: Name of the intervention treatment known to the subject and/or administrator. | G11: Req
A12: ECMOOD | B12: Mood | C12: Char | D12: (BRDGMOOD) | E12: Record Qualifier | F12: Mode or condition of the record specifying whether the intervention (activity) is intended to happen or has happened. Values align with BRIDG pillars (e.g., scheduled context, performed context) and HL7 activity moods (e.g., intent, event). Examples: "SCHEDULED", "PERFORMED". | G12: Perm
A13: ECCAT | B13: Category of Treatment | C13: Char | E13: Grouping Qualifier | F13: Used to define a category of related ECTRT values. | G13: Perm
A14: ECSCAT | B14: Subcategory of Treatment | C14: Char | E14: Grouping Qualifier | F14: A further categorization of ECCAT values. | G14: Perm
A15: ECPRESP | B15: Pre-Specified | C15: Char | D15: (NY) | E15: Variable Qualifier | F15: Used when a specific intervention is pre-specified. Values should be "Y" or null. | G15: Perm
A16: ECOCCUR | B16: Occurrence | C16: Char | D16: (NY) | E16: Record Qualifier | F16: Used to indicate whether a treatment occurred when information about the occurrence is solicited. ECOCCUR = "N" when a treatment was not taken, not given, or missed. | G16: Perm
A17: ECREASOC | B17: Reason for Occur Value | C17: Char | E17: Record Qualifier | F17: The reason for the value in --OCCUR. If --OCCUR = "N", this is the reason the exposure did not occur. | G17: Perm
A18: ECDOSE | B18: Dose | C18: Num | E18: Record Qualifier | F18: Amount of ECTRT when numeric. Not populated when ECDOSTXT is populated. | G18: Exp
A19: ECDOSTXT | B19: Dose Description | C19: Char | E19: Record Qualifier | F19: Amount of ECTRT when non-numeric. Dosing amounts or a range of dosing information collected in text form. Example: "200-400". Not populated when ECDOSE is populated. | G19: Perm
A20: ECDOSU | B20: Dose Units | C20: Char | D20: (UNIT) | E20: Variable Qualifier | F20: Units for ECDOSE, ECDOSTOT, or ECDOSTXT. | G20: Exp
A21: ECDOSFRM | B21: Dose Form | C21: Char | D21: (FRM) | E21: Variable Qualifier | F21: Dose form for ECTRT. Examples: "TABLET", "LOTION". | G21: Exp
A22: ECDOSFRQ | B22: Dosing Frequency per Interval | C22: Char | D22: (FREQ) | E22: Variable Qualifier | F22: Usually expressed as the number of repeated administrations of ECDOSE within a specific time period. Examples: "Q2H", "QD", "BID". | G22: Perm
A23: ECDOSTOT | B23: Total Daily Dose | C23: Num | E23: Record Qualifier | F23: Total daily dose of ECTRT using the units in ECDOSU. Used when dosing is collected as Total Daily Dose. | G23: Perm
A24: ECDOSRGM | B24: Intended Dose Regimen | C24: Char | E24: Variable Qualifier | F24: Text description of the intended schedule or regimen for the Intervention. Example: "TWO WEEKS ON", "TWO WEEKS OFF". | G24: Perm
A25: ECROUTE | B25: Route of Administration | C25: Char | D25: (ROUTE) | E25: Variable Qualifier | F25: Route of administration for the intervention. Examples: "ORAL", "INTRAVENOUS". | G25: Perm
A26: ECLOT | B26: Lot Number | C26: Char | E26: Record Qualifier | F26: Lot Number of the ECTRT product. | G26: Perm
A27: ECLOC | B27: Location of Dose Administration | C27: Char | D27: (LOC) | E27: Record Qualifier | F27: Specifies location of administration. Example: "ARM", "LIP". | G27: Perm
A28: ECLAT | B28: Laterality | C28: Char | D28: (LAT) | E28: Variable Qualifier | F28: Qualifier for anatomical location further detailing laterality of the intervention administration. Examples: "LEFT", "RIGHT". | G28: Perm
A29: ECDIR | B29: Directionality | C29: Char | D29: (DIR) | E29: Variable Qualifier | F29: Qualifier for anatomical location further detailing directionality. Examples: "ANTERIOR", "LOWER", "PROXIMAL", "UPPER". | G29: Perm
A30: ECPORTOT | B30: Portion or Totality | C30: Char | D30: (PORTOT) | E30: Variable Qualifier | F30: Qualifier for anatomical location further detailing distribution, which means arrangement of, apportioning of. Examples: "ENTIRE", "SINGLE", "SEGMENT". | G30: Perm
A31: ECFAST | B31: Fasting Status | C31: Char | D31: (NY) | E31: Record Qualifier | F31: Indicator used to identify fasting status. Examples: "Y", "N". | G31: Perm
A32: ECPSTRG | B32: Pharmaceutical Strength | C32: Num | E32: Record Qualifier | F32: Amount of an active ingredient expressed quantitatively per dosage unit, per unit of volume, or per unit of weight, according to the pharmaceutical dose form. | G32: Perm
A33: ECPSTRGU | B33: Pharmaceutical Strength Units | C33: Char | D33: (UNIT) | E33: Variable Qualifier | F33: Unit for ECPSTRG. Examples: "mg/TABLET", "mg/mL". | G33: Perm
A34: ECADJ | B34: Reason for Dose Adjustment | C34: Char | E34: Record Qualifier | F34: Describes reason or explanation of why a dose is adjusted. | G34: Perm
A35: TAETORD | B35: Planned Order of Element within Arm | C35: Num | E35: Timing | F35: Number that gives the planned order of the Element within the Arm. | G35: Perm
A36: EPOCH | B36: Epoch | C36: Char | D36: (EPOCH) | E36: Timing | F36: Trial Epoch of the exposure as collected record. Examples: "RUN-IN", "TREATMENT". | G36: Perm
A37: ECSTDTC | B37: Start Date/Time of Treatment | C37: Char | D37: ISO 8601 datetime or interval | E37: Timing | F37: The date/time when administration of the treatment indicated by ECTRT and ECDOSE began. | G37: Exp
A38: ECENDTC | B38: End Date/Time of Treatment | C38: Char | D38: ISO 8601 datetime or interval | E38: Timing | F38: The date/time when administration of the treatment indicated by ECTRT and ECDOSE ended. For administrations considered given at a point in time (e.g., oral tablet, pre-filled syringe injection), where only an administration date/time is collected, ECSTDTC should be copied to ECENDTC as the standard representation. | G38: Exp
A39: ECSTDY | B39: Study Day of Start of Treatment | C39: Num | E39: Timing | F39: Study day of ECSTDTC relative to the sponsor-defined DM.RFSTDTC. | G39: Perm
A40: ECENDY | B40: Study Day of End of Treatment | C40: Num | E40: Timing | F40: Study day of ECENDTC relative to the sponsor-defined DM.RFSTDTC. | G40: Perm
...

Sheet EX
A1: Variable Name | B1: Variable Label | C1: Type | D1: Controlled Terms, Codelist or Format | E1: Role | F1: CDISC Notes | G1: Core
A2: STUDYID | B2: Study Identifier | C2: Char | E2: Identifier | F2: Unique identifier for a study. | G2: Req
A3: DOMAIN | B3: Domain Abbreviation | C3: Char | D3: EX | E3: Identifier | F3: Two-character abbreviation for the domain. | G3: Req
A4: USUBJID | B4: Unique Subject Identifier | C4: Char | E4: Identifier | F4: Identifier used to uniquely identify a subject across all studies for all applications or submissions involving the product. | G4: Req
A5: EXSEQ | B5: Sequence Number | C5: Num | E5: Identifier | F5: Sequence Number given to ensure uniqueness of subject records within a domain. May be any valid number. | G5: Req
A6: EXGRPID | B6: Group ID | C6: Char | E6: Identifier | F6: Used to tie together a block of related records in a single domain for a subject. | G6: Perm
A7: EXREFID | B7: Reference ID | C7: Char | E7: Identifier | F7: Internal or external identifier (e.g., kit number, bottle label, vial identifier). | G7: Perm
A8: EXSPID | B8: Sponsor-Defined Identifier | C8: Char | E8: Identifier | F8: Sponsor-defined reference number. Perhaps pre-printed on the CRF as an explicit line identifier or defined in the sponsor's operational database. Example: Line number on a CRF Page. | G8: Perm
A9: EXLNKID | B9: Link ID | C9: Char | E9: Identifier | F9: Identifier used to link related records across domains. | G9: Perm
A10: EXLNKGRP | B10: Link Group ID | C10: Char | E10: Identifier | F10: Identifier used to link related, grouped records across domains. | G10: Perm
A11: EXTRT | B11: Name of Treatment | C11: Char | E11: Topic | F11: Name of the protocol-specified study treatment given during the dosing period for the observation. | G11: Req
A12: EXCAT | B12: Category of Treatment | C12: Char | E12: Grouping Qualifier | F12: Used to define a category of EXTRT values. | G12: Perm
A13: EXSCAT | B13: Subcategory of Treatment | C13: Char | E13: Grouping Qualifier | F13: A further categorization of EXCAT values. | G13: Perm
A14: EXDOSE | B14: Dose | C14: Num | E14: Record Qualifier | F14: Amount of EXTRT when numeric. Not populated when EXDOSTXT is populated. | G14: Exp
A15: EXDOSTXT | B15: Dose Description | C15: Char | E15: Record Qualifier | F15: Amount of EXTRT when non-numeric. Dosing amounts or a range of dosing information collected in text form. Example: 200-400. Not populated when EXDOSE is populated. | G15: Perm
A16: EXDOSU | B16: Dose Units | C16: Char | D16: (UNIT) | E16: Variable Qualifier | F16: Units for EXDOSE, EXDOSTOT, or EXDOSTXT representing protocol-specified values. Examples: "ng", "mg", "mg/kg", "mg/m2". | G16: Exp
A17: EXDOSFRM | B17: Dose Form | C17: Char | D17: (FRM) | E17: Variable Qualifier | F17: Dose form for EXTRT. Examples: "TABLET", "LOTION". | G17: Exp
A18: EXDOSFRQ | B18: Dosing Frequency per Interval | C18: Char | D18: (FREQ) | E18: Variable Qualifier | F18: Usually expressed as the number of repeated administrations of EXDOSE within a specific time period. Examples: "Q2H", "QD", "BID". | G18: Perm
A19: EXDOSRGM | B19: Intended Dose Regimen | C19: Char | E19: Variable Qualifier | F19: Text description of the intended schedule or regimen for the Intervention. Example: "TWO WEEKS ON, TWO WEEKS OFF". | G19: Perm
A20: EXROUTE | B20: Route of Administration | C20: Char | D20: (ROUTE) | E20: Variable Qualifier | F20: Route of administration for the intervention. Examples: "ORAL", "INTRAVENOUS". | G20: Perm
A21: EXLOT | B21: Lot Number | C21: Char | E21: Record Qualifier | F21: Lot number of the intervention product. | G21: Perm
A22: EXLOC | B22: Location of Dose Administration | C22: Char | D22: (LOC) | E22: Record Qualifier | F22: Specifies location of administration. Examples: "ARM", "LIP". | G22: Perm
A23: EXLAT | B23: Laterality | C23: Char | D23: (LAT) | E23: Variable Qualifier | F23: Qualifier for anatomical location further detailing laterality of the intervention administration. Examples: "LEFT", "RIGHT". | G23: Perm
A24: EXDIR | B24: Directionality | C24: Char | D24: (DIR) | E24: Variable Qualifier | F24: Qualifier for anatomical location further detailing directionality. Examples: "ANTERIOR", "LOWER", "PROXIMAL", "UPPER". | G24: Perm
A25: EXFAST | B25: Fasting Status | C25: Char | D25: (NY) | E25: Record Qualifier | F25: Indicator used to identify fasting status. Examples: "Y", "N". | G25: Perm
A26: EXADJ | B26: Reason for Dose Adjustment | C26: Char | E26: Record Qualifier | F26: Describes reason or explanation of why a dose is adjusted. | G26: Perm
A27: TAETORD | B27: Planned Order of Element within Arm | C27: Num | E27: Timing | F27: Number that gives the planned order of the Element within the Arm. | G27: Perm
A28: EPOCH | B28: Epoch | C28: Char | D28: (EPOCH) | E28: Timing | F28: Trial Epoch of the Exposure record. Examples: "RUN-IN", "TREATMENT". | G28: Perm
A29: EXSTDTC | B29: Start Date/Time of Treatment | C29: Char | D29: ISO 8601 datetime or interval | E29: Timing | F29: The date/time when administration of the treatment indicated by EXTRT and EXDOSE began. | G29: Exp
A30: EXENDTC | B30: End Date/Time of Treatment | C30: Char | D30: ISO 8601 datetime or interval | E30: Timing | F30: The date/time when administration of the treatment indicated by EXTRT and EXDOSE ended. For administrations considered given at a point in time (e.g., oral tablet, pre-filled syringe injection), where only an administration date/time is collected, EXSTDTC should be copied to EXENDTC as the standard representation. | G30: Exp
A31: EXSTDY | B31: Study Day of Start of Treatment | C31: Num | E31: Timing | F31: Study day of EXSTDTC relative to DM.RFSTDTC. | G31: Perm
A32: EXENDY | B32: Study Day of End of Treatment | C32: Num | E32: Timing | F32: Study day of EXENDTC relative to DM.RFSTDTC. | G32: Perm
A33: EXDUR | B33: Duration of Treatment | C33: Char | D33: ISO 8601 duration | E33: Timing | F33: Collected duration of administration. Used only if collected on the CRF and not derived from start and end date/times. | G33: Perm
A34: EXTPT | B34: Planned Time Point Name | C34: Char | E34: Timing | F34: 1. Text Description of time when administration should occur. 2. This may be represented as an elapsed time relative to a fixed reference point, such as time of last dose. See EXTPTNUM and EXTPTREF. | G34: Perm
A35: EXTPTNUM | B35: Planned Time Point Number | C35: Num | E35: Timing | F35: Numerical version of EXTPT to aid in sorting. | G35: Perm
A36: EXELTM | B36: Planned Elapsed Time from Time Point Ref | C36: Char | D36: ISO 8601 duration | E36: Timing | F36: Planned elapsed time relative to the planned fixed reference (EXTPTREF). This variable is useful where there are repetitive measures. Not a clock time. | G36: Perm
A37: EXTPTREF | B37: Time Point Reference | C37: Char | E37: Timing | F37: Name of the fixed reference point referred to by EXELTM, EXTPTNUM, and EXTPT. Examples: PREVIOUS DOSE, PREVIOUS MEAL. | G37: Perm
A38: EXRFTDTC | B38: Date/Time of Reference Time Point | C38: Char | D38: ISO 8601 datetime or interval | E38: Timing | F38: Date/time for a fixed reference time point defined by EXTPTREF. | G38: Perm

Sheet LB
A1: Variable Name | B1: Variable Label | C1: Type | D1: Controlled Terms, Codelist or Format | E1: Role | F1: CDISC Notes | G1: Core
A2: STUDYID | B2: Study Identifier | C2: Char | E2: Identifier | F2: Unique identifier for a study. | G2: Req
A3: DOMAIN | B3: Domain Abbreviation | C3: Char | D3: LB | E3: Identifier | F3: Two-character abbreviation for the domain. | G3: Req
A4: USUBJID | B4: Unique Subject Identifier | C4: Char | E4: Identifier | F4: Identifier used to uniquely identify a subject across all studies for all applications or submissions involving the product. | G4: Req
A5: LBSEQ | B5: Sequence Number | C5: Num | E5: Identifier | F5: Sequence number given to ensure uniqueness of subject records within a domain. May be any valid number. | G5: Req
A6: LBGRPID | B6: Group ID | C6: Char | E6: Identifier | F6: Used to tie together a block of related records in a single domain for a subject. | G6: Perm
A7: LBREFID | B7: Specimen ID | C7: Char | E7: Identifier | F7: Internal or external specimen identifier. Example: Specimen ID. | G7: Perm
A8: LBSPID | B8: Sponsor-Defined Identifier | C8: Char | E8: Identifier | F8: Sponsor-defined reference number. Perhaps preprinted on the CRF as an explicit line identifier or defined in the sponsor's operational database. Example: Line number on the Lab page. | G8: Perm
A9: LBTESTCD | B9: Lab Test or Examination Short Name. | C9: Char | D9: (LBTESTCD) | E9: Topic | F9: Short name of the measurement, test, or examination described in LBTEST. It can be used as a column name when converting a dataset from a vertical to a horizontal format. The value in LBTESTCD cannot be longer than 8 characters, nor can it start with a number (e.g., "1TEST" is not valid). LBTESTCD cannot contain characters other than letters, numbers, or underscores. Examples: "ALT", "LDH". | G9: Req
A10: LBTEST | B10: Lab Test or Examination Name | C10: Char | D10: (LBTEST) | E10: Synonym Qualifier | F10: Verbatim name of the test or examination used to obtain the measurement or finding. Note any test normally performed by a clinical laboratory is considered a lab test. The value in LBTEST cannot be longer than 40 characters. Examples: "Alanine Aminotransferase", "Lactate Dehydrogenase". | G10: Req
A11: LBTSTCND | B11: Test Condition | C11: Char | D11: (TESTCOND) | E11: Variable Qualifier | F11: Identifies any planned condition imposed by the assay system on the specimen at the time the test is performed. | G11: Perm
A12: LBBDAGNT | B12: Binding Agent | C12: Char | E12: Variable Qualifier | F12: The textual description of the agent that is binding to the entity in the LBTEST variable. The LBBDAGNT variable is used to indicate that there is a binding relationship between the entities in the LBTEST and LBBDAGNT variables, regardless of direction. LBBDAGNT is not a method qualifier. It should only be used when the actual interest of the measurement is the binding interaction between the 2 entities in LBTEST and LBBDAGNT. In other words, the combination of LBTEST and LBBDAGNT should describe the thing, the entity, or the analyte being measured, without the need for additional variables. The binding agent may be (but is not limited to) a test article, a portion of the test article, a related compound, or an endogenous molecule. | G12: Perm
A13: LBTSTOPO | B13: Test Operational Objective | C13: Char | D13: (TSTOPOBJ) | E13: Variable Qualifier | F13: Text description of the high-level purpose of the test at the operational level. | G13: Perm
A14: LBCAT | B14: Category for Lab Test | C14: Char | E14: Grouping Qualifier | F14: Used to define a category of related records across subjects. Examples: "HEMATOLOGY", "URINALYSIS", "CHEMISTRY". | G14: Exp
A15: LBSCAT | B15: Subcategory for Lab Test | C15: Char | E15: Grouping Qualifier | F15: A further categorization of a test category such as "DIFFERENTIAL", "COAGULATION", "LIVER FUNCTION", "ELECTROLYTES". | G15: Perm
A16: LBORRES | B16: Result or Finding in Original Units | C16: Char | E16: Result Qualifier | F16: Result of the measurement or finding as originally received or collected. | G16: Exp
A17: LBORRESU | B17: Original Units | C17: Char | D17: (UNIT) | E17: Variable Qualifier | F17: Original units in which the data were collected. The unit for LBORRES. Example: "g/L". | G17: Exp
A18: LBRESSCL | B18: Result Scale | C18: Char | D18: (RSLSCLRS) | E18: Record Qualifier | F18: Classifies the scale of the original result value; for example, whether the result is ordinal, nominal, quantitative, or narrative. | G18: Perm
A19: LBRESTYP | B19: Result Type | C19: Char | D19: (RESTYPRS) | E19: Record Qualifier | F19: Classifies the kind of result (i.e., property type) originally reported for the test. Examples include substance concentration, proportion, mass rate, and arbitrary concentration. | G19: Perm
A20: LBCOLSRT | B20: Collected Summary Result Type | C20: Char | D20: (COLSTYP) | E20: Record Qualifier | F20: Used to indicate the type of collected summary result. This includes source summary results collected on a CRF or provided by an external vendor (e.g., central lab). If the summary result is derived by the sponsor using individual source data records from SDTM, the derived summary result is represented in ADaM. If the summary result is produced and reported by the lab, the collected summary result is represented in SDTM. | G20: Perm
A21: LBORNRLO | B21: Reference Range Lower Limit in Orig Unit | C21: Char | E21: Variable Qualifier | F21: Lower end of reference range for continuous measurement in original units. Should be populated only for continuous results. | G21: Exp
A22: LBORNRHI | B22: Reference Range Upper Limit in Orig Unit | C22: Char | E22: Variable Qualifier | F22: Upper end of reference range for continuous measurement in original units. Should be populated only for continuous results. | G22: Exp
A23: LBLLOD | B23: Lower Limit of Detection | C23: Char | E23: Variable Qualifier | F23: The lowest threshold (as originally received or collected) for reliably detecting the presence or absence of substance measured by a specific test. The value for the field will be as described in documentation from the instrument or lab vendor. | G23: Perm
A24: LBSTRESC | B24: Character Result/Finding in Std Format | C24: Char | D24: (LBSTRESC) | E24: Result Qualifier | F24: Contains the result value for all findings, copied or derived from LBORRES in a standard format or standard units. LBSTRESC should store all results or findings in character format; if results are numeric, they should also be stored in numeric format in LBSTRESN. For example, if a test has results "NONE", "NEG", and "NEGATIVE" in LBORRES and these results effectively have the same meaning, they could be represented in standard format in LBSTRESC as "NEGATIVE". For other examples, see general assumptions. | G24: Exp
A25: LBSTRESN | B25: Numeric Result/Finding in Standard Units | C25: Num | E25: Result Qualifier | F25: Used for continuous or numeric results or findings in standard format; copied in numeric format from LBSTRESC. LBSTRESN should store all numeric test results or findings. | G25: Exp
A26: LBSTRESU | B26: Standard Units | C26: Char | D26: (UNIT) | E26: Variable Qualifier | F26: Standardized unit used for LBSTRESC or LBSTRESN. | G26: Exp
A27: LBSTNRLO | B27: Reference Range Lower Limit-Std Units | C27: Num | E27: Variable Qualifier | F27: Lower end of reference range for continuous measurements for LBSTRESC/LBSTRESN in standardized units. Should be populated only for continuous results. | G27: Exp
A28: LBSTNRHI | B28: Reference Range Upper Limit-Std Units | C28: Num | E28: Variable Qualifier | F28: Upper end of reference range for continuous measurements in standardized units. Should be populated only for continuous results. | G28: Exp
A29: LBSTNRC | B29: Reference Range for Char Rslt-Std Units | C29: Char | E29: Variable Qualifier | F29: For normal range values that are character in ordinal scale or if categorical ranges were supplied (e.g., "-1 to +1", "NEGATIVE TO TRACE"). | G29: Perm
A30: LBNRIND | B30: Reference Range Indicator | C30: Char | D30: (NRIND) | E30: Variable Qualifier | F30: 1. Indicates where the value falls with respect to reference range defined by LBORNRLO and LBORNRHI, LBSTNRLO and LBSTNRHI, or by LBSTNRC. Examples: "NORMAL", "ABNORMAL", "HIGH", "LOW". 2. Sponsors should specify in the study metadata (Comments column in the Define-XML document) whether LBNRIND refers to the original or standard reference ranges and results. 3. Should not be used to indicate clinical significance. | G30: Exp
A31: LBSTAT | B31: Completion Status | C31: Char | D31: (ND) | E31: Record Qualifier | F31: Used to indicate exam not done. Should be null if a result exists in LBORRES. | G31: Perm
A32: LBREASND | B32: Reason Test Not Done | C32: Char | E32: Record Qualifier | F32: Describes why a measurement or test was not performed, e.g., "BROKEN EQUIPMENT", "SUBJECT REFUSED", or "SPECIMEN LOST". Used in conjunction with LBSTAT when value is "NOT DONE". | G32: Perm
A33: LBNAM | B33: Vendor Name | C33: Char | E33: Record Qualifier | F33: The name or identifier of the laboratory that performed the test. | G33: Perm
A34: LBLOINC | B34: LOINC Code | C34: Char | E34: Synonym Qualifier | F34: 1. Code for the lab test from the LOINC code system. 2. The sponsor is expected to provide the dictionary name and version used to map the terms utilizing the Define-XML external codelist attributes. | G34: Perm
A35: LBSPEC | B35: Specimen Type | C35: Char | D35: (SPECTYPE) | E35: Record Qualifier | F35: Defines the type of specimen used for a measurement. Examples: "SERUM", "PLASMA", "URINE", "DNA", "RNA". | G35: Perm
A36: LBSPCCND | B36: Specimen Condition | C36: Char | D36: (SPECCOND) | E36: Record Qualifier | F36: Free or standardized text describing the condition of the specimen, e.g., "HEMOLYZED", "ICTERIC", "LIPEMIC". | G36: Perm
A37: LBSPCUFL | B37: Specimen Usability for the Test | C37: Char | D37: (NY) | E37: Record Qualifier | F37: Describes the usability of the specimen for the test. The value will be "N" if the specimen is not usable, and null if the specimen is usable. | G37: Perm
A38: LBMETHOD | B38: Method of Test or Examination | C38: Char | D38: (METHOD) | E38: Record Qualifier | F38: Method of the test or examination. Examples: "EIA" (Enzyme Immunoassay), "ELECTROPHORESIS", "DIPSTICK". | G38: Perm
A39: LBANMETH | B39: Analysis Method | C39: Char | D39: (LBANMET) | E39: Record Qualifier | F39: Analysis method applied to obtain a summarized result. Analysis method describes the method of secondary processing applied to a complex observation result (e.g., a calculation used to measure eGFR). | G39: Perm
A40: LBTMTHSN | B40: Test Method Sensitivity | C40: Char | D40: (TSTMTHSN) | E40: Record Qualifier | F40: The sensitivity of the test methodology with respect to observation, detection, or quantification. | G40: Perm
...

Sheet CM
A1: Variable Name | B1: Variable Label | C1: Type | D1: Controlled Terms, Codelist or Format | E1: Role | F1: CDISC Notes | G1: Core
A2: STUDYID | B2: Study Identifier | C2: Char | E2: Identifier | F2: Unique identifier for a study. | G2: Req
A3: DOMAIN | B3: Domain Abbreviation | C3: Char | D3: CM | E3: Identifier | F3: Two-character abbreviation for the domain. | G3: Req
A4: USUBJID | B4: Unique Subject Identifier | C4: Char | E4: Identifier | F4: Identifier used to uniquely identify a subject across all studies for all applications or submissions involving the product. | G4: Req
A5: CMSEQ | B5: Sequence Number | C5: Num | E5: Identifier | F5: Sequence number to ensure uniqueness of subject records within a domain. May be any valid number. | G5: Req
A6: CMGRPID | B6: Group ID | C6: Char | E6: Identifier | F6: Used to tie together a block of related records in a single domain for a subject. | G6: Perm
A7: CMSPID | B7: Sponsor-Defined Identifier | C7: Char | E7: Identifier | F7: Sponsor-defined reference number. Example: a number pre-printed on the CRF as an explicit line identifier or record identifier defined in the sponsor's operational database. Example: line number on a concomitant medication page. | G7: Perm
A8: CMTRT | B8: Reported Name of Drug, Med, or Therapy | C8: Char | E8: Topic | F8: Verbatim medication name that is either pre-printed or collected on a CRF. | G8: Req
A9: CMMODIFY | B9: Modified Reported Name | C9: Char | E9: Synonym Qualifier | F9: If CMTRT is modified to facilitate coding, then CMMODIFY will contain the modified text. | G9: Perm
A10: CMDECOD | B10: Standardized Medication Name | C10: Char | E10: Synonym Qualifier | F10: Standardized or dictionary-derived text description of CMTRT or CMMODIFY. Equivalent to the generic drug name in WHO Drug. The sponsor is expected to provide the dictionary name and version used to map the terms utilizing the external codelist element in the Define-XML document. If an intervention term does not have a decode value in the dictionary, then CMDECOD will be left blank. | G10: Perm
A11: CMCAT | B11: Category for Medication | C11: Char | E11: Grouping Qualifier | F11: Used to define a category of medications/treatment. Examples: "PRIOR", "CONCOMITANT", "ANTI-CANCER MEDICATION", or "GENERAL CONMED". | G11: Perm
A12: CMSCAT | B12: Subcategory for Medication | C12: Char | E12: Grouping Qualifier | F12: A further categorization of medications/treatment. Examples: "CHEMOTHERAPY", "HORMONAL THERAPY", "ALTERNATIVE THERAPY". | G12: Perm
A13: CMPRESP | B13: CM Pre-specified | C13: Char | D13: (NY) | E13: Variable Qualifier | F13: Used to indicate whether ("Y"/null) information about the use of a specific medication was solicited on the CRF. | G13: Perm
A14: CMOCCUR | B14: CM Occurrence | C14: Char | D14: (NY) | E14: Record Qualifier | F14: When the use of a specific medication is solicited. CMOCCUR is used to indicate whether or not ("Y"/"N") use of the medication occurred. Values are null for medications not specifically solicited. | G14: Perm
A15: CMSTAT | B15: Completion Status | C15: Char | D15: (ND) | E15: Record Qualifier | F15: Used to indicate that a question about the occurrence of a pre-specified intervention was not answered. Should be null or have a value of "NOT DONE". | G15: Perm
A16: CMREASND | B16: Reason Medication Not Collected | C16: Char | E16: Record Qualifier | F16: Reason not done. Used in conjunction with CMSTAT when value is "NOT DONE". | G16: Perm
A17: CMINDC | B17: Indication | C17: Char | E17: Record Qualifier | F17: Denotes why a medication was taken or administered. Examples: "NAUSEA", "HYPERTENSION". | G17: Perm
A18: CMCLAS | B18: Medication Class | C18: Char | E18: Variable Qualifier | F18: Drug class. May be obtained from coding. When coding to a single class, populate with class value. If using a dictionary and coding to multiple classes, then follow Section 4.2.8.3, Multiple Values for a Non-Result Qualifier Variable, or omit CMCLAS. | G18: Perm
A19: CMCLASCD | B19: Medication Class Code | C19: Char | E19: Variable Qualifier | F19: Class code corresponding to CMCLAS. Drug class. May be obtained from coding. When coding to a single class, populate with class code. If using a dictionary and coding to multiple classes, then follow Section 4.2.8.3, Multiple Values for a Non-Result Qualifier Variable, or omit CMCLASCD. | G19: Perm
A20: CMDOSE | B20: Dose per Administration | C20: Num | E20: Record Qualifier | F20: Amount of CMTRT given. Not populated when CMDOSTXT is populated. | G20: Perm
A21: CMDOSTXT | B21: Dose Description | C21: Char | E21: Record Qualifier | F21: Dosing amounts or a range of dosing information collected in text form. Units may be stored in CMDOSU. Examples: "200-400", "15-20". Not populated when CMDOSE is populated. | G21: Perm
A22: CMDOSU | B22: Dose Units | C22: Char | D22: (UNIT) | E22: Variable Qualifier | F22: Units for CMDOSE, CMDOSTOT, or CMDOSTXT. Examples: "ng", "mg", or "mg/kg". | G22: Perm
A23: CMDOSFRM | B23: Dose Form | C23: Char | D23: (FRM) | E23: Variable Qualifier | F23: Dose form for CMTRT. Examples: "TABLET", "LOTION". | G23: Perm
A24: CMDOSFRQ | B24: Dosing Frequency per Interval | C24: Char | D24: (FREQ) | E24: Variable Qualifier | F24: Usually expressed as the number of repeated administrations of CMDOSE within a specific time period. Examples: "BID" (twice daily), "Q12H" (every 12 hours). | G24: Perm
A25: CMDOSTOT | B25: Total Daily Dose | C25: Num | E25: Record Qualifier | F25: Total daily dose of CMTRT using the units in CMDOSU. Used when dosing is collected as Total Daily Dose. Total dose over a period other than day could be recorded in a separate Supplemental Qualifier variable. | G25: Perm
A26: CMDOSRGM | B26: Intended Dose Regimen | C26: Char | E26: Variable Qualifier | F26: Text description of the (intended) schedule or regimen for the Intervention. Example: "TWO WEEKS ON, TWO WEEKS OFF". | G26: Perm
A27: CMROUTE | B27: Route of Administration | C27: Char | D27: (ROUTE) | E27: Variable Qualifier | F27: Route of administration for the intervention. Examples: "ORAL", "INTRAVENOUS". | G27: Perm
A28: CMADJ | B28: Reason for Dose Adjustment | C28: Char | E28: Record Qualifier | F28: Describes reason or explanation of why a dose is adjusted. Examples: "ADVERSE EVENT", "INSUFFICIENT RESPONSE", "NON-MEDICAL REASON". | G28: Perm
A29: CMRSDISC | B29: Reason the Intervention Was Discontinued | C29: Char | E29: Record Qualifier | F29: When dosing of a treatment is recorded over multiple successive records, this variable is applicable only for the (chronologically) last record for the treatment. | G29: Perm
A30: TAETORD | B30: Planned Order of Element within Arm | C30: Num | E30: Timing | F30: Number that gives the planned order of the Element within the Arm for the Element in which the medication administration started. Null for medications that started before study participation. | G30: Perm
A31: EPOCH | B31: Epoch | C31: Char | D31: (EPOCH) | E31: Timing | F31: Epoch associated with the start date/time of the medication administration. Null for medications that started before study participation. | G31: Perm
A32: CMSTDTC | B32: Start Date/Time of Medication | C32: Char | D32: ISO 8601 | E32: Timing | F32: Start date/time of the medication administration represented in ISO 8601 character format. | G32: Perm
A33: CMENDTC | B33: End Date/Time of Medication | C33: Char | D33: ISO 8601 | E33: Timing | F33: End date/time of the medication administration represented in ISO 8601 character format. | G33: Perm
A34: CMSTDY | B34: Study Day of Start of Medication | C34: Num | E34: Timing | F34: Study day of start of medication relative to the sponsor-defined RFSTDTC. | G34: Perm
A35: CMENDY | B35: Study Day of End of Medication | C35: Num | E35: Timing | F35: Study day of end of medication relative to the sponsor-defined RFSTDTC. | G35: Perm
A36: CMDUR | B36: Duration | C36: Char | D36: ISO 8601 | E36: Timing | F36: Collected duration for a treatment episode. Used only if collected on the CRF and not derived from start and end date/times. | G36: Perm
A37: CMSTRF | B37: Start Relative to Reference Period | C37: Char | D37: (STENRF) | E37: Timing | F37: Describes the start of the medication relative to sponsor-defined reference period. The sponsor-defined reference period is a continuous period of time defined by a discrete starting point and a discrete ending point (represented by RFSTDTC and RFENDTC in Demographics). If information such as "PRIOR" was collected, this information may be translated into CMSTRF. Not all values of the codelist are allowable for this variable. See Section 4.4.7, Use of Relative Timing Variables. | G37: Perm
A38: CMENRF | B38: End Relative to Reference Period | C38: Char | D38: (STENRF) | E38: Timing | F38: Describes the end of the medication relative to the sponsor-defined reference period. The sponsor-defined reference period is a continuous period of time defined by a discrete starting point and a discrete ending point (represented by RFSTDTC and RFENDTC in Demographics). If information such as "PRIOR", "ONGOING, or "CONTINUING" was collected, this information may be translated into CMENRF. Not all values of the codelist are allowable for this variable. See Section 4.4.7, Use of Relative Timing Variables. | G38: Perm
A39: CMSTRTPT | B39: Start Relative to Reference Time Point | C39: Char | D39: (STENRF) | E39: Timing | F39: Identifies the start of the medication as being before or after the sponsor-defined reference time point defined by variable CMSTTPT. Not all values of the codelist are allowable for this variable. See Section 4.4.7, Use of Relative Timing Variables. | G39: Perm
A40: CMSTTPT | B40: Start Reference Time Point | C40: Char | E40: Timing | F40: Description or date/time in ISO 8601 character format of the sponsor-defined reference point referred to by CMSTRTPT. Examples: "2003-12-15" or "VISIT 1". | G40: Perm
...

Sheet VS
A1: Variable Name | B1: Variable Label | C1: Type | D1: Controlled Terms, Codelist or Format | E1: Role | F1: CDISC Notes | G1: Core
A2: STUDYID | B2: Study Identifier | C2: Char | E2: Identifier | F2: Unique identifier for a study. | G2: Req
A3: DOMAIN | B3: Domain Abbreviation | C3: Char | D3: VS | E3: Identifier | F3: Two-character abbreviation for the domain. | G3: Req
A4: USUBJID | B4: Unique Subject Identifier | C4: Char | E4: Identifier | F4: Identifier used to uniquely identify a subject across all studies for all applications or submissions involving the product. | G4: Req
A5: VSSEQ | B5: Sequence Number | C5: Num | E5: Identifier | F5: Sequence number given to ensure uniqueness of subject records within a domain. May be any valid number. | G5: Req
A6: VSGRPID | B6: Group ID | C6: Char | E6: Identifier | F6: Used to tie together a block of related records in a single domain for a subject. | G6: Perm
A7: VSSPID | B7: Sponsor-Defined Identifier | C7: Char | E7: Identifier | F7: Sponsor-defined reference number. Perhaps pre-printed on the CRF as an explicit line identifier or defined in the sponsor's operational database. | G7: Perm
A8: VSTESTCD | B8: Vital Signs Test Short Name | C8: Char | D8: (VSTESTCD) | E8: Topic | F8: Short name of the measurement, test, or examination described in VSTEST. It can be used as a column name when converting a dataset from a vertical to a horizontal format. The value in VSTESTCD cannot be longer than 8 characters, nor can it start with a number (e.g., "1TEST" is not valid). VSTESTCD cannot contain characters other than letters, numbers, or underscores. Examples: "SYSBP", "DIABP", "BMI". | G8: Req
A9: VSTEST | B9: Vital Signs Test Name | C9: Char | D9: (VSTEST) | E9: Synonym Qualifier | F9: Verbatim name of the test or examination used to obtain the measurement or finding. The value in VSTEST cannot be longer than 40 characters. Examples: "Systolic Blood Pressure", "Diastolic Blood Pressure", "Body Mass Index". | G9: Req
A10: VSCAT | B10: Category for Vital Signs | C10: Char | E10: Grouping Qualifier | F10: Used to define a category of related records. | G10: Perm
A11: VSSCAT | B11: Subcategory for Vital Signs | C11: Char | E11: Grouping Qualifier | F11: A further categorization of a measurement or examination. | G11: Perm
A12: VSPOS | B12: Vital Signs Position of Subject | C12: Char | D12: (POSITION) | E12: Record Qualifier | F12: Position of the subject during a measurement or examination. Examples: "SUPINE", "STANDING", "SITTING". | G12: Perm
A13: VSORRES | B13: Result or Finding in Original Units | C13: Char | E13: Result Qualifier | F13: Result of the vital signs measurement as originally received or collected. | G13: Exp
